<?xml version="1.0"?>
<robot name="tortoisebot">
	<link name="base_link">
		<visual>
			<geometry>
				<box size="0.6 0.3 0.1"/>
			</geometry>
		<material name="silver">
			<color rgba="0.75 0.75 0.75 1"/>
		</material>
		</visual>
	</link>
	<!-- right wheel link-->
 <link name="right_wheel">
    <visual>
      <geometry>
        <cylinder length="0.05" radius="0.075"/>
      </geometry>
      <material name="black"/>
    </visual>
    <collision>
      <geometry>
        <cylinder length="0.05" radius="0.035"/>
      </geometry>
    </collision>
    <inertial>
      <mass value="0.1"/>
      <inertia ixx="5.1458e-5" iyy="5.1458e-5" izz="6.125e-5" ixy="0" ixz="0" iyz="0"/>
    </inertial>
  </link>
  <!-- left wheel link-->
  <link name="left_wheel">
    <visual>
      <geometry>
        <cylinder length="0.05" radius="0.05"/>
      </geometry>
      <material name="black"/>
    </visual>
    <collision>
      <geometry>
        <cylinder length="0.05" radius="0.035"/>
      </geometry>
    </collision>
    <inertial>
      <mass value="0.1"/>
      <inertia ixx="5.1458e-5" iyy="5.1458e-5" izz="6.125e-5" ixy="0" ixz="0" iyz="0"/>
    </inertial>
  </link>
  <!-- caster support-->
  <link name="caster_support">
    <visual>
      <material name="black"/>
    </visual>
    <visual>
      <geometry>
        <sphere radius="0.06"/>
      </geometry>
    </visual>
    <collision>
      <geometry>
        <cylinder length="0.05" radius="0.035"/>
      </geometry>1
    </collision>
    <inertial>
      <mass value="0.1"/>
      <inertia ixx="5.1458e-5" iyy="5.1458e-5" izz="6.125e-5" ixy="0" ixz="0" iyz="0"/>
    </inertial>
  </link>
  <!-- right wheel joint-->
  <joint name="right_wheel_joint" type="continuous">
    <axis xyz="0 0 1"/>
    <parent link="base_link"/>
    <child link="right_wheel"/>
    <origin rpy="-1.5708 0 0" xyz="0.2 0.176 -0.05"/>
  </joint>
  <!-- left wheel joint-->
  <joint name="left_wheel_joint" type="continuous">
    <axis xyz="0 0 1"/>
    <parent link="base_link"/>
    <child link="left_wheel"/>
    <origin rpy="-1.5708 0 0" xyz="0.2 -0.176 -0.05"/>
  </joint>
  <!-- caster support joint-->
  <joint name="caster_wheel_joint" type="continuous">
    <axis xyz="0 0 1"/>
    <parent link="base_link"/>
    <child link="caster_support"/>
    <origin rpy="0 0 0" xyz="-0.2 0.0 -0.05"/>
  </joint>

</robot>
