<?xml version="1.0"?>
<robot name="bot"
    xmlns:xacro="http://www.ros.org/wiki/xacro">

    <xacro:include filename="$(find flipbot2_description)/urdf/materials.xacro" />
    <xacro:include filename="$(find flipbot2_description)/urdf/bot.trans" />
    <xacro:include filename="$(find flipbot2_description)/urdf/bot.gazebo" />

    <xacro:arg name="index" default='1' />
    <xacro:arg name="index_1" default='False' />
    <xacro:arg name="index_2" default='False' />
    <xacro:arg name="index_3" default='False' />
    <xacro:arg name="index_4" default='False' />
    <xacro:property name="castor_mount_link_length_width_height" value="0.1145 0.10 0.0057" />
    <xacro:property name="castor_mount_link_length" value="0.1145" />
    <xacro:property name="castor_mount_link_width" value="0.10" />
    <xacro:property name="castor_mount_link_height" value="0.0057" />
    <xacro:property name="castor_mount_link_mass" value="0.25"/> <!--0.25 kg-->
    <xacro:property name="castor_wheel_length" value="0.049" />
    <xacro:property name="castor_wheel_radius" value="0.07925" />
    <xacro:property name="castor_wheel_mass" value="2"/> <!--2 kg-->
    <link name="dummy">
    </link>

    <link name="base_link">
        <inertial>
            <origin rpy="0 0 0" xyz="0 0 0.02" />
            <mass value="0.11050949445484062" />
            <inertia ixx="9e-05" ixy="-0.0" ixz="-1e-06" iyy="9.3e-05" iyz="0.0" izz="0.00018" />
        </inertial>
        <visual>
            <origin rpy="0 0 0" xyz="0 0 0.02" />
            <geometry>
                <box size="0.13 0.13 0.005"/>

                <!-- <mesh filename="package://flipbot2_description/meshes/base.stl" scale="0.001 0.001 0.001" /> -->
            </geometry>
        </visual>
        <collision>
            <origin rpy="0 0 0" xyz="0 0 0 " />
            <geometry>
                <box size="0.6 0.1 0.2"/>

                <!-- <mesh filename="package://flipbot_description/meshes/base.stl" scale="0.001 0.001 0.001" /> -->
            </geometry>
        </collision>
    </link>


    <link name="aruco_tag">
        <visual>
            <origin rpy="0 0 0" xyz="0 0 0.12" />
            <xacro:if value="$(arg index_1)">
                <geometry>
                    <mesh filename="package://flipbot_description/meshes/ID_1.dae" scale="1 1 1" />
                </geometry>
            </xacro:if>
            <xacro:if value="$(arg index_2)">
                <geometry>
                    <mesh filename="package://flipbot_description/meshes/ID_2.dae" scale="1 1 1" />
                </geometry>
            </xacro:if>
            <xacro:if value="$(arg index_3)">
                <geometry>
                    <mesh filename="package://flipbot_description/meshes/ID_3.dae" scale="1 1 1" />
                </geometry>
            </xacro:if>
            <xacro:if value="$(arg index_4)">
                <geometry>
                    <mesh filename="package://flipbot_description/meshes/ID_4.dae" scale="1 1 1" />
                </geometry>
            </xacro:if>
        </visual>

    </link>

    <link name="rear_wheel_right_link">
        <inertial>
            <origin rpy="-1.5708 0 0" xyz="0 0 0" />
            <mass value="0.1" />
            <inertia ixx="0.000014256" ixy="0.0" ixz="0.0" iyy="0.000014256" iyz="-0.0" izz="0.000023113" />

        </inertial>
        <visual>
            <origin rpy="-1.5708 0 0" xyz="0 0 0" />

            <geometry>
                <cylinder length="0.018" radius="0.0215" />
            </geometry>
            <material name="black">
                <color rgba="0 0 0 1" />
            </material>
        </visual>
        <collision>
            <origin rpy="-1.5708 0 0" xyz="0 0 0" />
            <geometry>
                <cylinder length="0.018" radius="0.0215" />
            </geometry>
        </collision>
    </link>

    <link name="rear_wheel_left_link">
        <inertial>
            <origin rpy="-1.5708 0 0" xyz="0 0 0" />
            <mass value="0.1" />
            <inertia ixx="0.000014256" ixy="0.0" ixz="0.0" iyy="0.000014256" iyz="-0.0" izz="0.000023113" />
        </inertial>
        <visual>
            <origin rpy="-1.5708 0 0" xyz="0 0 0" />
            <geometry>
                <cylinder length="0.018" radius="0.0215" />
            </geometry>
            <material name="black">
                <color rgba="0 0 0 1" />
            </material>
        </visual>
        <collision>
            <origin rpy="-1.5708 0 0" xyz="0 0 0" />
            <geometry>
                <cylinder length="0.018" radius="0.0215" />
            </geometry>
        </collision>
    </link>


    <link name="castor_mount">
        <inertial>
            <origin rpy="-1.5708 0 0" xyz="0 0 0" />
            <mass value="0.1" />
            <inertia ixx="0.000014256" ixy="0.0" ixz="0.0" iyy="0.000014256" iyz="-0.0" izz="0.000023113" />
        </inertial>
        <visual>
            <origin rpy="-1.5708 0 0" xyz="0 0 0" />
            <geometry>
                <cylinder length="0.005" radius="0.01" />
            </geometry>
            <material name="black">
                <color rgba="0 0 0 1" />
            </material>
        </visual>
        <collision>
            <origin rpy="-1.5708 0 0" xyz="0 0 0" />
            <geometry>
                <cylinder length="0.018" radius="0.0215" />
            </geometry>
        </collision>
    </link>
    
    
    <link name="castor_mount_rear">
        <inertial>
            <origin rpy="-1.5708 0 0" xyz="0 0 0" />
            <mass value="0.1" />
            <inertia ixx="0.000014256" ixy="0.0" ixz="0.0" iyy="0.000014256" iyz="-0.0" izz="0.000023113" />
        </inertial>
        <visual>
            <origin rpy="-1.5708 0 0" xyz="0 0 0" />
            <geometry>
                <cylinder length="0.005" radius="0.01" />
            </geometry>
            <material name="black">
                <color rgba="0 0 0 1" />
            </material>
        </visual>
        <collision>
            <origin rpy="-1.5708 0 0" xyz="0 0 0" />
            <geometry>
                <cylinder length="0.018" radius="0.0215" />
            </geometry>
        </collision>
    </link>
    

    <!-- dummy link -->
    <joint name="dummy_joint" type="fixed">
        <parent link="dummy"/>
        <child link="base_link"/>
    </joint>
    <!-- aruco tags -->
    <joint name="aruco_joint" type="fixed">
        <parent link="base_link" />
        <child link="aruco_tag" />
        <origin rpy="0 0 0" xyz="0 0 0" />
    </joint>
    <!-- leftwheel -->
    <joint name="right_joint" type="continuous">
        <parent link="base_link" />
        <child link="rear_wheel_right_link" />
        <origin rpy="0 0 0" xyz="0.0 0.06 0.0215" />
        <axis xyz="0 1 0" />
        <limit effort="10000" velocity="1000" />
        <joint_properties damping="1.0" friction="1.0" />
    </joint>
    <joint name="left_joint" type="continuous">
        <parent link="base_link" />
        <child link="rear_wheel_left_link" />
        <origin rpy="0 0 0" xyz="0.0 -0.06 0.0215" />
        <axis xyz="0 1 0" />
        <limit effort="10000" velocity="1000" />
        <joint_properties damping="1.0" friction="1.0" />
    </joint>
    <joint name="caster_joint" type="continuous">
        <parent link="base_link" />
        <child link="castor_mount_rear" />
        <origin rpy="0 0 0" xyz="-0.05 0 0.0082" />
        <axis xyz="0 1 0" />
        <limit effort="10000" velocity="1000" />
        <joint_properties damping="1.0" friction="1.0" />
    </joint>
    <joint name="caster_joint_rear" type="continuous">
        <parent link="base_link" />
        <child link="castor_mount" />
        <origin rpy="0 0 0" xyz="0.05 0 0.0082" />
        <axis xyz="0 1 0" />
        <limit effort="10000" velocity="1000" />
        <joint_properties damping="1.0" friction="1.0" />
    </joint>
    
   

</robot>
