<?xml version="1.0" ?>
<!-- =================================================================================== -->
<!-- |    This document was autogenerated by xacro from diffbot.urdf.xacro             | -->
<!-- |    EDITING THIS FILE BY HAND IS NOT RECOMMENDED                                 | -->
<!-- =================================================================================== -->
<robot name="diffbot">
  <!-- ======================================================================= -->
  <!-- ========================================================================-->
  <!-- ===================== Material ============================================

  RVIZ material RGBA definition.
-->
  <material name="blue">
    <color rgba="0 0 0.8 1"/>
  </material>
  <material name="black">
    <color rgba="0 0 0 1"/>
  </material>
  <material name="white">
    <color rgba="1 1 1 1"/>
  </material>
  <material name="red">
    <color rgba="0.8 0.0 0.0 1.0"/>
  </material>
  <material name="silver">
    <color rgba="0.79 0.82 0.93 1"/>
  </material>
  <material name="dark_grey">
    <color rgba="0.3 0.3 0.3 1"/>
  </material>
  <!-- ========================================================================-->
  <!-- ===================== Caster xacro =========================================

  Xacro to create caster links and the respective joints. For more detail information and usage, see:
    https://github.com/pxalcantara/mobile_robot_description/wiki/Motor-xacro

  params:
  - prefix [string]: used to diferentiate the link and joint name;
  - reflect [1/-1]: value to set the side of the caster;
  - wheel_props [dictionary]: wheel properties;
  - base_props [dictionary]: base link properties;
  - mesh [string]: file name of the wheel mesh;
    - DEFAULT Value -> Empty string
-->
  <!-- Base-Footprint -->
  <!-- base_footprint is a fictitious link(frame) that is on the ground right below base_link origin -->
  <link name="base_footprint"/>
  <!-- Joint to connect base_footprint with base_link -->
  <joint name="base_footprint_joint" type="fixed">
    <parent link="base_footprint"/>
    <child link="base_link"/>
    <!-- origin xyz="0 0 ${wheel_radius - base_z_origin_to_wheel_origin}" rpy="0 0 0" /-->
    <!-- origin xyz="0 0 ${wheel_props['radius'] - wheel_props['z_offset'] + 0.1}" rpy="0 0 0" /-->
    <origin rpy="0 0 0" xyz="0 0 0.0501"/>
  </joint>
  <link name="base_link">
    <inertial>
      <mass value="0.8"/>
      <inertia ixx="0.00042833333333333335" ixy="0.0" ixz="0.0" iyy="0.0025366666666666667" iyz="0.0" izz="0.002961666666666667"/>
      <origin rpy="0.0 0.0 0.0" xyz="0.0 0.0 0.0"/>
    </inertial>
    <visual>
      <origin rpy="0 0 0" xyz="0 0 0"/>
      <geometry>
        <mesh filename="package://diffbot_description/meshes/diffbot/chassis.stl"/>
      </geometry>
      <material name="white"/>
    </visual>
    <collision>
      <origin rpy="0.0 0.0 0.0" xyz="0.0 0.0 0.0"/>
      <geometry>
        <box size="0.195 0.08 0.005"/>
      </geometry>
    </collision>
  </link>
  <!-- caster base (fixed) -->
  <link name="rear_caster_base_link">
    <inertial>
      <mass value="0.02"/>
      <inertia ixx="5.333333333333334e-06" ixy="0.0" ixz="0.0" iyy="5.333333333333334e-06" iyz="0.0" izz="5.333333333333334e-06"/>
      <origin rpy="0.0 0.0 0.0" xyz="0.0 0.0 -0.02"/>
    </inertial>
    <visual>
      <origin rpy="0 0 0" xyz="0 0 -0.02"/>
      <geometry>
        <mesh filename="package://diffbot_description/meshes/diffbot/caster_base.stl"/>
      </geometry>
      <!-- xacro:insert_block name="material_silver" / TODO use this block? -->
      <material name="silver"/>
    </visual>
    <collision>
      <origin rpy="0 0 0" xyz="0 0 -0.02"/>
      <geometry>
        <box size="0.04 0.04 0.04"/>
      </geometry>
    </collision>
  </link>
  <joint name="rear_caster_base_joint" type="fixed">
    <origin rpy="0 0 0" xyz="-0.076 -0.0 0.0045"/>
    <parent link="base_link"/>
    <child link="rear_caster_base_link"/>
    <axis xyz="0 0 1"/>
    <dynamics damping="0.01" friction="0.0"/>
  </joint>
  <gazebo reference="rear_caster_base_link">
    <material>Gazebo/Grey</material>
  </gazebo>
  <!-- caster hub -->
  <link name="rear_caster_rotation_link">
    <inertial>
      <mass value="0.02"/>
      <inertia ixx="5.333333333333334e-06" ixy="0.0" ixz="0.0" iyy="5.333333333333334e-06" iyz="0.0" izz="5.333333333333334e-06"/>
      <origin rpy="0.0 0.0 0.0" xyz="0.0 0.0 -0.02"/>
    </inertial>
    <visual>
      <origin rpy="0 0 0" xyz="0 0 -0.02"/>
      <geometry>
        <mesh filename="package://diffbot_description/meshes/diffbot/caster_wheel_support.stl"/>
      </geometry>
      <!-- xacro:insert_block name="material_silver" / TODO use this block? -->
      <material name="silver"/>
    </visual>
    <collision>
      <origin rpy="0 0 0" xyz="0 0 -0.02"/>
      <geometry>
        <box size="0.04 0.04 0.04"/>
      </geometry>
    </collision>
  </link>
  <joint name="rear_caster_rotation_joint" type="continuous">
    <origin rpy="0 0 0" xyz="-0.077 -0.0 0.0045"/>
    <parent link="base_link"/>
    <child link="rear_caster_rotation_link"/>
    <axis xyz="0 0 1"/>
    <dynamics damping="0.01" friction="0.0"/>
  </joint>
  <gazebo reference="rear_caster_rotation_link">
    <material>Gazebo/Grey</material>
  </gazebo>
  <!-- caster wheel -->
  <link name="rear_caster_wheel_link">
    <inertial>
      <mass value="0.5"/>
      <inertia ixx="3.229166666666667e-05" ixy="0" ixz="0" iyy="3.229166666666667e-05" iyz="0" izz="5.625e-05"/>
      <origin rpy="0.0 0.0 0.0" xyz="0.0 0.0 0.0"/>
    </inertial>
    <visual>
      <origin rpy="0 0 0" xyz="0 0 0"/>
      <geometry>
        <mesh filename="package://diffbot_description/meshes/diffbot/caster_wheel.stl"/>
      </geometry>
      <!-- TODO use this?: xacro:insert_block name="material_dark_grey" /-->
      <material name="black"/>
    </visual>
    <collision>
      <origin rpy="1.5707963267948966 0 0" xyz="0 0 0"/>
      <geometry>
        <cylinder length="0.01" radius="0.015"/>
      </geometry>
    </collision>
  </link>
  <joint name="rear_caster_wheel_joint" type="continuous">
    <origin rpy="0 0 0" xyz="-0.016 0 -0.04"/>
    <parent link="rear_caster_rotation_link"/>
    <child link="rear_caster_wheel_link"/>
    <axis xyz="0 1 0"/>
  </joint>
  <gazebo reference="rear_caster_wheel_link">
    <material>Gazebo/DarkGrey</material>
  </gazebo>
  <link name="front_right_wheel">
    <visual>
      <origin rpy="1.5707963267948966 0 -3.141592653589793" xyz="0.0 0 0"/>
      <geometry>
        <mesh filename="package://diffbot_description/meshes/diffbot/../components/wheel.stl"/>
        <mesh filename="package://diffbot_description/meshes/diffbot/../components/wheel.stl" scale=""/>
      </geometry>
      <material name="dark_grey"/>
    </visual>
    <collision>
      <origin rpy="1.5707963267948966 0 0" xyz="0 0 0"/>
      <geometry>
        <cylinder length="0.025" radius="0.0331"/>
      </geometry>
    </collision>
    <inertial>
      <mass value="0.5"/>
      <inertia ixx="0.00016299291666666666" ixy="0" ixz="0" iyy="0.00016299291666666666" iyz="0" izz="0.0002739025"/>
      <origin rpy="1.5707963267948966 0.0 0.0" xyz="0.0 0.0 0.0"/>
    </inertial>
  </link>
  <gazebo reference="front_right_wheel">
    <material>Gazebo/Grey</material>
  </gazebo>
  <joint name="front_right_wheel_joint" type="continuous">
    <axis rpy="0 0 0" xyz="0 1 0"/>
    <parent link="base_link"/>
    <child link="front_right_wheel"/>
    <origin rpy="0 0 0" xyz="0.018500000000000003 -0.0675 -0.017"/>
  </joint>
  <transmission name="front_right_wheel_transmission">
    <type>transmission_interface/SimpleTransmission</type>
    <joint name="front_right_wheel_joint">
      <hardwareInterface>hardware_interface/VelocityJointInterface</hardwareInterface>
    </joint>
    <actuator name="front_right_motor">
      <hardwareInterface>hardware_interface/VelocityJointInterface</hardwareInterface>
      <mechanicalReduction>1</mechanicalReduction>
    </actuator>
  </transmission>
  <link name="front_left_wheel">
    <visual>
      <origin rpy="1.5707963267948966 0 0.0" xyz="0.0 0 0"/>
      <geometry>
        <mesh filename="package://diffbot_description/meshes/diffbot/../components/wheel.stl"/>
        <mesh filename="package://diffbot_description/meshes/diffbot/../components/wheel.stl" scale=""/>
      </geometry>
      <material name="dark_grey"/>
    </visual>
    <collision>
      <origin rpy="1.5707963267948966 0 0" xyz="0 0 0"/>
      <geometry>
        <cylinder length="0.025" radius="0.0331"/>
      </geometry>
    </collision>
    <inertial>
      <mass value="0.5"/>
      <inertia ixx="0.00016299291666666666" ixy="0" ixz="0" iyy="0.00016299291666666666" iyz="0" izz="0.0002739025"/>
      <origin rpy="1.5707963267948966 0.0 0.0" xyz="0.0 0.0 0.0"/>
    </inertial>
  </link>
  <gazebo reference="front_left_wheel">
    <material>Gazebo/Grey</material>
  </gazebo>
  <joint name="front_left_wheel_joint" type="continuous">
    <axis rpy="0 0 0" xyz="0 1 0"/>
    <parent link="base_link"/>
    <child link="front_left_wheel"/>
    <origin rpy="0 0 0" xyz="0.018500000000000003 0.0675 -0.017"/>
  </joint>
  <transmission name="front_left_wheel_transmission">
    <type>transmission_interface/SimpleTransmission</type>
    <joint name="front_left_wheel_joint">
      <hardwareInterface>hardware_interface/VelocityJointInterface</hardwareInterface>
    </joint>
    <actuator name="front_left_motor">
      <hardwareInterface>hardware_interface/VelocityJointInterface</hardwareInterface>
      <mechanicalReduction>1</mechanicalReduction>
    </actuator>
  </transmission>
  <link name="right_motor">
    <visual>
      <origin rpy="0.0 0 -3.141592653589793" xyz="0.0 0.0 0.0"/>
      <geometry>
        <mesh filename="package://diffbot_description/meshes/diffbot/motor.stl"/>
      </geometry>
      <material name="blue"/>
    </visual>
    <collision>
      <origin rpy="1.5707963267948966 0 0" xyz="0 0 0"/>
      <geometry>
        <box size="0.07 0.0225 0.0188"/>
      </geometry>
    </collision>
    <inertial>
      <mass value="0.1"/>
      <inertia ixx="7.164083333333333e-06" ixy="0.0" ixz="0.0" iyy="4.3778666666666675e-05" iyz="0.0" izz="4.505208333333334e-05"/>
      <origin rpy="0.0 0.0 0.0" xyz="0.0 0.0 0.0"/>
    </inertial>
  </link>
  <joint name="right_motor_joint" type="fixed">
    <parent link="base_link"/>
    <child link="right_motor"/>
    <origin rpy="0 3.141592653589793 0" xyz="0.0015000000000000013 -0.037750000000000006 -0.017"/>
    <axis rpy="0 0 0" xyz="0 1 0"/>
    <!--origin xyz="${transX} ${reflect * (transY - wheel_width)} ${transZ}" rpy="${-pi/2.0*(reflect - 1)} 0 0" /-->
    <!--axis xyz="0 1 0" rpy="0 0 ${pi/2.0*(reflect - 1)}" /-->
  </joint>
  <gazebo reference="right_motor">
    <material>Gazebo/SkyBlue</material>
    <turnGravityOff>false</turnGravityOff>
  </gazebo>
  <link name="left_motor">
    <visual>
      <origin rpy="0.0 0 0.0" xyz="0.0 0.0 0.0"/>
      <geometry>
        <mesh filename="package://diffbot_description/meshes/diffbot/motor.stl"/>
      </geometry>
      <material name="blue"/>
    </visual>
    <collision>
      <origin rpy="1.5707963267948966 0 0" xyz="0 0 0"/>
      <geometry>
        <box size="0.07 0.0225 0.0188"/>
      </geometry>
    </collision>
    <inertial>
      <mass value="0.1"/>
      <inertia ixx="7.164083333333333e-06" ixy="0.0" ixz="0.0" iyy="4.3778666666666675e-05" iyz="0.0" izz="4.505208333333334e-05"/>
      <origin rpy="0.0 0.0 0.0" xyz="0.0 0.0 0.0"/>
    </inertial>
  </link>
  <joint name="left_motor_joint" type="fixed">
    <parent link="base_link"/>
    <child link="left_motor"/>
    <origin rpy="0 -0.0 0" xyz="0.0015000000000000013 0.037750000000000006 -0.017"/>
    <axis rpy="0 0 0" xyz="0 1 0"/>
    <!--origin xyz="${transX} ${reflect * (transY - wheel_width)} ${transZ}" rpy="${-pi/2.0*(reflect - 1)} 0 0" /-->
    <!--axis xyz="0 1 0" rpy="0 0 ${pi/2.0*(reflect - 1)}" /-->
  </joint>
  <gazebo reference="left_motor">
    <material>Gazebo/SkyBlue</material>
    <turnGravityOff>false</turnGravityOff>
  </gazebo>
  <link name="rplidar_gpu_laser_link">
    <visual>
      <origin rpy="0 0 0" xyz="0 0 0"/>
      <geometry>
        <mesh filename="package://diffbot_description/meshes/sensors/rplidar-a2.stl"/>
      </geometry>
      <material name="dark_grey"/>
    </visual>
    <collision>
      <origin rpy="0 0 0" xyz="0 0 0"/>
      <geometry>
        <cylinder length="0.01" radius="0.015"/>
      </geometry>
    </collision>
    <inertial>
      <mass value="0.1"/>
      <inertia ixx="6.458333333333333e-06" ixy="0" ixz="0" iyy="6.458333333333333e-06" iyz="0" izz="1.1249999999999999e-05"/>
      <origin rpy="0 0 0" xyz="0 0 0"/>
    </inertial>
  </link>
  <gazebo reference="rplidar_gpu_laser_link">
    <material>Gazebo/Grey</material>
  </gazebo>
  <joint name="rplidar_gpu_laser_joint" type="fixed">
    <parent link="base_link"/>
    <child link="rplidar_gpu_laser_link"/>
    <origin rpy="0 0 0" xyz="0.0 0.0 0.04"/>
    <axis xyz="0 1 0"/>
  </joint>
  <!-- hokuyo gazebo references -->
  <gazebo reference="rplidar_gpu_laser_link">
    <sensor name="head_hokuyo_sensor" type="gpu_ray">
      <pose>0 0 0 0 0 0</pose>
      <visualize>true</visualize>
      <update_rate>40</update_rate>
      <ray>
        <scan>
          <horizontal>
            <samples>720</samples>
            <resolution>1</resolution>
            <min_angle>-3.1415</min_angle>
            <max_angle>3.1415</max_angle>
          </horizontal>
        </scan>
        <range>
          <min>0.10</min>
          <max>30.0</max>
          <resolution>0.01</resolution>
        </range>
        <noise>
          <type>gaussian</type>
          <!--Noise parameters based on published spec for Hokuyo laser
               achieving "+-30mm" accuracy at range < 10m.  A mean of 0.0m and
               stddev of 0.01m will put 99.7% of samples within 0.03m of the true
               reading. -->
          <mean>0.0</mean>
          <stddev>0.01</stddev>
        </noise>
      </ray>
      <plugin filename="libgazebo_ros_gpu_laser.so" name="gazebo_ros_head_hokuyo_controller">
        <topicName>/diffbot/scan</topicName>
        <frameName>rplidar_gpu_laser_link</frameName>
      </plugin>
    </sensor>
  </gazebo>
  <gazebo>
    <plugin filename="libgazebo_ros_control.so" name="gazebo_ros_control">
      <robotNamespace>/diffbot</robotNamespace>
      <!--robotParam>/robot_description</robotParam-->
      <robotSimType>gazebo_ros_control/DefaultRobotHWSim</robotSimType>
    </plugin>
  </gazebo>
</robot>

